06.01.2020-14:44:29: ContextScope: java.lang.AssertionError: other launches should be cancelled as well.message
de.gapps.utils.coroutines.ExceptionTest$testWithContext$1$result$3$1.invokeSuspend(ExceptionTest.kt:81)
de.gapps.utils.coroutines.ExceptionTest$testWithContext$1$result$3$1.invoke(ExceptionTest.kt)
de.gapps.utils.coroutines.builder.ExecuteExInternalKt.executeExInternal(ExecuteExInternal.kt:40)
de.gapps.utils.coroutines.builder.ExecuteExInternalKt$executeExInternal$1.invokeSuspend(ExecuteExInternal.kt)
kotlin.coroutines.jvm.internal.BaseContinuationImpl.resumeWith(ContinuationImpl.kt:33)
kotlinx.coroutines.ResumeModeKt.resumeMode(ResumeMode.kt:67)
kotlinx.coroutines.DispatchedKt.resume(Dispatched.kt:319)
kotlinx.coroutines.DispatchedKt.dispatch(Dispatched.kt:301)
kotlinx.coroutines.CancellableContinuationImpl.dispatchResume(CancellableContinuationImpl.kt:250)
kotlinx.coroutines.CancellableContinuationImpl.resumeImpl(CancellableContinuationImpl.kt:260)
kotlinx.coroutines.CancellableContinuationImpl.resumeUndispatched(CancellableContinuationImpl.kt:332)
kotlinx.coroutines.EventLoopImplBase$DelayedResumeTask.run(EventLoop.common.kt:483)
kotlinx.coroutines.EventLoopImplBase.processNextEvent(EventLoop.common.kt:270)
kotlinx.coroutines.BlockingCoroutine.joinBlocking(Builders.kt:79)
kotlinx.coroutines.BuildersKt__BuildersKt.runBlocking(Builders.kt:54)
kotlinx.coroutines.BuildersKt.runBlocking(Unknown Source)
kotlinx.coroutines.BuildersKt__BuildersKt.runBlocking$default(Builders.kt:36)
kotlinx.coroutines.BuildersKt.runBlocking$default(Unknown Source)
de.gapps.utils.coroutines.ExceptionTest.testWithContext(ExceptionTest.kt:67)
java.base/jdk.internal.reflect.NativeMethodAccessorImpl.invoke0(Native Method)
java.base/jdk.internal.reflect.NativeMethodAccessorImpl.invoke(NativeMethodAccessorImpl.java:62)
java.base/jdk.internal.reflect.DelegatingMethodAccessorImpl.invoke(DelegatingMethodAccessorImpl.java:43)
java.base/java.lang.reflect.Method.invoke(Method.java:566)
kotlin.reflect.jvm.internal.calls.CallerImpl$Method.callMethod(CallerImpl.kt:97)
kotlin.reflect.jvm.internal.calls.CallerImpl$Method$Instance.call(CallerImpl.kt:113)
kotlin.reflect.jvm.internal.KCallableImpl.call(KCallableImpl.kt:106)
kotlin.reflect.full.KCallables.callSuspend(KCallables.kt:51)
io.kotlintest.specs.AbstractAnnotationSpec$createTestCase$1.invokeSuspend(AbstractAnnotationSpec.kt:80)
io.kotlintest.specs.AbstractAnnotationSpec$createTestCase$1.invoke(AbstractAnnotationSpec.kt)
io.kotlintest.runner.jvm.TestCaseExecutor$executeTest$supervisorJob$1$invokeSuspend$$inlined$map$lambda$1.invokeSuspend(TestCaseExecutor.kt:133)
kotlin.coroutines.jvm.internal.BaseContinuationImpl.resumeWith(ContinuationImpl.kt:33)
kotlinx.coroutines.DispatchedTask.run(Dispatched.kt:241)
java.base/java.util.concurrent.ThreadPoolExecutor.runWorker(ThreadPoolExecutor.java:1128)
java.base/java.util.concurrent.ThreadPoolExecutor$Worker.run(ThreadPoolExecutor.java:628)
java.base/java.lang.Thread.run(Thread.java:834)


06.01.2020-14:44:29: ContextScope: java.lang.Throwable: throw inside withContextEx.message
de.gapps.utils.coroutines.ExceptionTest$testWithContext$1$result$3.invokeSuspend(ExceptionTest.kt:82)
de.gapps.utils.coroutines.ExceptionTest$testWithContext$1$result$3.invoke(ExceptionTest.kt)
de.gapps.utils.coroutines.builder.ExecuteExInternalKt.executeExInternal(ExecuteExInternal.kt:40)
de.gapps.utils.coroutines.builder.WithContextExKt$withContextEx$2.invokeSuspend(WithContextEx.kt:33)
de.gapps.utils.coroutines.builder.WithContextExKt$withContextEx$2.invoke(WithContextEx.kt)
kotlinx.coroutines.intrinsics.UndispatchedKt.startUndispatchedOrReturn(Undispatched.kt:91)
kotlinx.coroutines.BuildersKt__Builders_commonKt.withContext(Builders.common.kt:156)
kotlinx.coroutines.BuildersKt.withContext(Unknown Source)
de.gapps.utils.coroutines.builder.WithContextExKt.withContextEx(WithContextEx.kt:26)
de.gapps.utils.coroutines.builder.WithContextExKt.withContextEx$default(WithContextEx.kt:24)
de.gapps.utils.coroutines.ExceptionTest$testWithContext$1.invokeSuspend(ExceptionTest.kt:72)
kotlin.coroutines.jvm.internal.BaseContinuationImpl.resumeWith(ContinuationImpl.kt:33)
kotlinx.coroutines.DispatchedTask.run(Dispatched.kt:241)
kotlinx.coroutines.EventLoopImplBase.processNextEvent(EventLoop.common.kt:270)
kotlinx.coroutines.BlockingCoroutine.joinBlocking(Builders.kt:79)
kotlinx.coroutines.BuildersKt__BuildersKt.runBlocking(Builders.kt:54)
kotlinx.coroutines.BuildersKt.runBlocking(Unknown Source)
kotlinx.coroutines.BuildersKt__BuildersKt.runBlocking$default(Builders.kt:36)
kotlinx.coroutines.BuildersKt.runBlocking$default(Unknown Source)
de.gapps.utils.coroutines.ExceptionTest.testWithContext(ExceptionTest.kt:67)
java.base/jdk.internal.reflect.NativeMethodAccessorImpl.invoke0(Native Method)
java.base/jdk.internal.reflect.NativeMethodAccessorImpl.invoke(NativeMethodAccessorImpl.java:62)
java.base/jdk.internal.reflect.DelegatingMethodAccessorImpl.invoke(DelegatingMethodAccessorImpl.java:43)
java.base/java.lang.reflect.Method.invoke(Method.java:566)
kotlin.reflect.jvm.internal.calls.CallerImpl$Method.callMethod(CallerImpl.kt:97)
kotlin.reflect.jvm.internal.calls.CallerImpl$Method$Instance.call(CallerImpl.kt:113)
kotlin.reflect.jvm.internal.KCallableImpl.call(KCallableImpl.kt:106)
kotlin.reflect.full.KCallables.callSuspend(KCallables.kt:51)
io.kotlintest.specs.AbstractAnnotationSpec$createTestCase$1.invokeSuspend(AbstractAnnotationSpec.kt:80)
io.kotlintest.specs.AbstractAnnotationSpec$createTestCase$1.invoke(AbstractAnnotationSpec.kt)
io.kotlintest.runner.jvm.TestCaseExecutor$executeTest$supervisorJob$1$invokeSuspend$$inlined$map$lambda$1.invokeSuspend(TestCaseExecutor.kt:133)
kotlin.coroutines.jvm.internal.BaseContinuationImpl.resumeWith(ContinuationImpl.kt:33)
kotlinx.coroutines.DispatchedTask.run(Dispatched.kt:241)
java.base/java.util.concurrent.ThreadPoolExecutor.runWorker(ThreadPoolExecutor.java:1128)
java.base/java.util.concurrent.ThreadPoolExecutor$Worker.run(ThreadPoolExecutor.java:628)
java.base/java.lang.Thread.run(Thread.java:834)


06.01.2020-14:44:29: ContextScope: java.lang.AssertionError: other launches should be cancelled as well.message
de.gapps.utils.coroutines.ExceptionTest$testLaunch$1$3$1.invokeSuspend(ExceptionTest.kt:29)
de.gapps.utils.coroutines.ExceptionTest$testLaunch$1$3$1.invoke(ExceptionTest.kt)
de.gapps.utils.coroutines.builder.ExecuteExInternalKt.executeExInternal(ExecuteExInternal.kt:40)
de.gapps.utils.coroutines.builder.ExecuteExInternalKt$executeExInternal$1.invokeSuspend(ExecuteExInternal.kt)
kotlin.coroutines.jvm.internal.BaseContinuationImpl.resumeWith(ContinuationImpl.kt:33)
kotlinx.coroutines.ResumeModeKt.resumeMode(ResumeMode.kt:67)
kotlinx.coroutines.DispatchedKt.resume(Dispatched.kt:319)
kotlinx.coroutines.DispatchedKt.dispatch(Dispatched.kt:301)
kotlinx.coroutines.CancellableContinuationImpl.dispatchResume(CancellableContinuationImpl.kt:250)
kotlinx.coroutines.CancellableContinuationImpl.resumeImpl(CancellableContinuationImpl.kt:260)
kotlinx.coroutines.CancellableContinuationImpl.resumeUndispatched(CancellableContinuationImpl.kt:332)
kotlinx.coroutines.EventLoopImplBase$DelayedResumeTask.run(EventLoop.common.kt:483)
kotlinx.coroutines.EventLoopImplBase.processNextEvent(EventLoop.common.kt:270)
kotlinx.coroutines.BlockingCoroutine.joinBlocking(Builders.kt:79)
kotlinx.coroutines.BuildersKt__BuildersKt.runBlocking(Builders.kt:54)
kotlinx.coroutines.BuildersKt.runBlocking(Unknown Source)
kotlinx.coroutines.BuildersKt__BuildersKt.runBlocking$default(Builders.kt:36)
kotlinx.coroutines.BuildersKt.runBlocking$default(Unknown Source)
de.gapps.utils.coroutines.ExceptionTest.testLaunch(ExceptionTest.kt:17)
java.base/jdk.internal.reflect.NativeMethodAccessorImpl.invoke0(Native Method)
java.base/jdk.internal.reflect.NativeMethodAccessorImpl.invoke(NativeMethodAccessorImpl.java:62)
java.base/jdk.internal.reflect.DelegatingMethodAccessorImpl.invoke(DelegatingMethodAccessorImpl.java:43)
java.base/java.lang.reflect.Method.invoke(Method.java:566)
kotlin.reflect.jvm.internal.calls.CallerImpl$Method.callMethod(CallerImpl.kt:97)
kotlin.reflect.jvm.internal.calls.CallerImpl$Method$Instance.call(CallerImpl.kt:113)
kotlin.reflect.jvm.internal.KCallableImpl.call(KCallableImpl.kt:106)
kotlin.reflect.full.KCallables.callSuspend(KCallables.kt:51)
io.kotlintest.specs.AbstractAnnotationSpec$createTestCase$1.invokeSuspend(AbstractAnnotationSpec.kt:80)
io.kotlintest.specs.AbstractAnnotationSpec$createTestCase$1.invoke(AbstractAnnotationSpec.kt)
io.kotlintest.runner.jvm.TestCaseExecutor$executeTest$supervisorJob$1$invokeSuspend$$inlined$map$lambda$1.invokeSuspend(TestCaseExecutor.kt:133)
kotlin.coroutines.jvm.internal.BaseContinuationImpl.resumeWith(ContinuationImpl.kt:33)
kotlinx.coroutines.DispatchedTask.run(Dispatched.kt:241)
java.base/java.util.concurrent.ThreadPoolExecutor.runWorker(ThreadPoolExecutor.java:1128)
java.base/java.util.concurrent.ThreadPoolExecutor$Worker.run(ThreadPoolExecutor.java:628)
java.base/java.lang.Thread.run(Thread.java:834)


06.01.2020-14:44:29: ContextScope: java.lang.Throwable: throw inside launchEx.message
de.gapps.utils.coroutines.ExceptionTest$testLaunch$1$3.invokeSuspend(ExceptionTest.kt:30)
de.gapps.utils.coroutines.ExceptionTest$testLaunch$1$3.invoke(ExceptionTest.kt)
de.gapps.utils.coroutines.builder.ExecuteExInternalKt.executeExInternal(ExecuteExInternal.kt:40)
de.gapps.utils.coroutines.builder.LaunchExKt$launchEx$1.invokeSuspend(LaunchEx.kt:57)
kotlin.coroutines.jvm.internal.BaseContinuationImpl.resumeWith(ContinuationImpl.kt:33)
kotlinx.coroutines.DispatchedTask.run(Dispatched.kt:241)
kotlinx.coroutines.EventLoopImplBase.processNextEvent(EventLoop.common.kt:270)
kotlinx.coroutines.BlockingCoroutine.joinBlocking(Builders.kt:79)
kotlinx.coroutines.BuildersKt__BuildersKt.runBlocking(Builders.kt:54)
kotlinx.coroutines.BuildersKt.runBlocking(Unknown Source)
kotlinx.coroutines.BuildersKt__BuildersKt.runBlocking$default(Builders.kt:36)
kotlinx.coroutines.BuildersKt.runBlocking$default(Unknown Source)
de.gapps.utils.coroutines.ExceptionTest.testLaunch(ExceptionTest.kt:17)
java.base/jdk.internal.reflect.NativeMethodAccessorImpl.invoke0(Native Method)
java.base/jdk.internal.reflect.NativeMethodAccessorImpl.invoke(NativeMethodAccessorImpl.java:62)
java.base/jdk.internal.reflect.DelegatingMethodAccessorImpl.invoke(DelegatingMethodAccessorImpl.java:43)
java.base/java.lang.reflect.Method.invoke(Method.java:566)
kotlin.reflect.jvm.internal.calls.CallerImpl$Method.callMethod(CallerImpl.kt:97)
kotlin.reflect.jvm.internal.calls.CallerImpl$Method$Instance.call(CallerImpl.kt:113)
kotlin.reflect.jvm.internal.KCallableImpl.call(KCallableImpl.kt:106)
kotlin.reflect.full.KCallables.callSuspend(KCallables.kt:51)
io.kotlintest.specs.AbstractAnnotationSpec$createTestCase$1.invokeSuspend(AbstractAnnotationSpec.kt:80)
io.kotlintest.specs.AbstractAnnotationSpec$createTestCase$1.invoke(AbstractAnnotationSpec.kt)
io.kotlintest.runner.jvm.TestCaseExecutor$executeTest$supervisorJob$1$invokeSuspend$$inlined$map$lambda$1.invokeSuspend(TestCaseExecutor.kt:133)
kotlin.coroutines.jvm.internal.BaseContinuationImpl.resumeWith(ContinuationImpl.kt:33)
kotlinx.coroutines.DispatchedTask.run(Dispatched.kt:241)
java.base/java.util.concurrent.ThreadPoolExecutor.runWorker(ThreadPoolExecutor.java:1128)
java.base/java.util.concurrent.ThreadPoolExecutor$Worker.run(ThreadPoolExecutor.java:628)
java.base/java.lang.Thread.run(Thread.java:834)


06.01.2020-14:44:29: ContextScope: java.lang.AssertionError: other launches should be cancelled as well.message
de.gapps.utils.coroutines.ExceptionTest$testAsync$1$result$3$1.invokeSuspend(ExceptionTest.kt:54)
de.gapps.utils.coroutines.ExceptionTest$testAsync$1$result$3$1.invoke(ExceptionTest.kt)
de.gapps.utils.coroutines.builder.ExecuteExInternalKt.executeExInternal(ExecuteExInternal.kt:40)
de.gapps.utils.coroutines.builder.ExecuteExInternalKt$executeExInternal$1.invokeSuspend(ExecuteExInternal.kt)
kotlin.coroutines.jvm.internal.BaseContinuationImpl.resumeWith(ContinuationImpl.kt:33)
kotlinx.coroutines.ResumeModeKt.resumeMode(ResumeMode.kt:67)
kotlinx.coroutines.DispatchedKt.resume(Dispatched.kt:319)
kotlinx.coroutines.DispatchedKt.dispatch(Dispatched.kt:301)
kotlinx.coroutines.CancellableContinuationImpl.dispatchResume(CancellableContinuationImpl.kt:250)
kotlinx.coroutines.CancellableContinuationImpl.resumeImpl(CancellableContinuationImpl.kt:260)
kotlinx.coroutines.CancellableContinuationImpl.resumeUndispatched(CancellableContinuationImpl.kt:332)
kotlinx.coroutines.EventLoopImplBase$DelayedResumeTask.run(EventLoop.common.kt:483)
kotlinx.coroutines.EventLoopImplBase.processNextEvent(EventLoop.common.kt:270)
kotlinx.coroutines.BlockingCoroutine.joinBlocking(Builders.kt:79)
kotlinx.coroutines.BuildersKt__BuildersKt.runBlocking(Builders.kt:54)
kotlinx.coroutines.BuildersKt.runBlocking(Unknown Source)
kotlinx.coroutines.BuildersKt__BuildersKt.runBlocking$default(Builders.kt:36)
kotlinx.coroutines.BuildersKt.runBlocking$default(Unknown Source)
de.gapps.utils.coroutines.ExceptionTest.testAsync(ExceptionTest.kt:41)
java.base/jdk.internal.reflect.NativeMethodAccessorImpl.invoke0(Native Method)
java.base/jdk.internal.reflect.NativeMethodAccessorImpl.invoke(NativeMethodAccessorImpl.java:62)
java.base/jdk.internal.reflect.DelegatingMethodAccessorImpl.invoke(DelegatingMethodAccessorImpl.java:43)
java.base/java.lang.reflect.Method.invoke(Method.java:566)
kotlin.reflect.jvm.internal.calls.CallerImpl$Method.callMethod(CallerImpl.kt:97)
kotlin.reflect.jvm.internal.calls.CallerImpl$Method$Instance.call(CallerImpl.kt:113)
kotlin.reflect.jvm.internal.KCallableImpl.call(KCallableImpl.kt:106)
kotlin.reflect.full.KCallables.callSuspend(KCallables.kt:51)
io.kotlintest.specs.AbstractAnnotationSpec$createTestCase$1.invokeSuspend(AbstractAnnotationSpec.kt:80)
io.kotlintest.specs.AbstractAnnotationSpec$createTestCase$1.invoke(AbstractAnnotationSpec.kt)
io.kotlintest.runner.jvm.TestCaseExecutor$executeTest$supervisorJob$1$invokeSuspend$$inlined$map$lambda$1.invokeSuspend(TestCaseExecutor.kt:133)
kotlin.coroutines.jvm.internal.BaseContinuationImpl.resumeWith(ContinuationImpl.kt:33)
kotlinx.coroutines.DispatchedTask.run(Dispatched.kt:241)
java.base/java.util.concurrent.ThreadPoolExecutor.runWorker(ThreadPoolExecutor.java:1128)
java.base/java.util.concurrent.ThreadPoolExecutor$Worker.run(ThreadPoolExecutor.java:628)
java.base/java.lang.Thread.run(Thread.java:834)


06.01.2020-14:44:29: ContextScope: java.lang.Throwable: throw inside asyncEx.message
de.gapps.utils.coroutines.ExceptionTest$testAsync$1$result$3.invokeSuspend(ExceptionTest.kt:55)
de.gapps.utils.coroutines.ExceptionTest$testAsync$1$result$3.invoke(ExceptionTest.kt)
de.gapps.utils.coroutines.builder.ExecuteExInternalKt.executeExInternal(ExecuteExInternal.kt:40)
de.gapps.utils.coroutines.builder.AsyncExKt$asyncEx$1.invokeSuspend(AsyncEx.kt:28)
kotlin.coroutines.jvm.internal.BaseContinuationImpl.resumeWith(ContinuationImpl.kt:33)
kotlinx.coroutines.DispatchedTask.run(Dispatched.kt:241)
kotlinx.coroutines.EventLoopImplBase.processNextEvent(EventLoop.common.kt:270)
kotlinx.coroutines.BlockingCoroutine.joinBlocking(Builders.kt:79)
kotlinx.coroutines.BuildersKt__BuildersKt.runBlocking(Builders.kt:54)
kotlinx.coroutines.BuildersKt.runBlocking(Unknown Source)
kotlinx.coroutines.BuildersKt__BuildersKt.runBlocking$default(Builders.kt:36)
kotlinx.coroutines.BuildersKt.runBlocking$default(Unknown Source)
de.gapps.utils.coroutines.ExceptionTest.testAsync(ExceptionTest.kt:41)
java.base/jdk.internal.reflect.NativeMethodAccessorImpl.invoke0(Native Method)
java.base/jdk.internal.reflect.NativeMethodAccessorImpl.invoke(NativeMethodAccessorImpl.java:62)
java.base/jdk.internal.reflect.DelegatingMethodAccessorImpl.invoke(DelegatingMethodAccessorImpl.java:43)
java.base/java.lang.reflect.Method.invoke(Method.java:566)
kotlin.reflect.jvm.internal.calls.CallerImpl$Method.callMethod(CallerImpl.kt:97)
kotlin.reflect.jvm.internal.calls.CallerImpl$Method$Instance.call(CallerImpl.kt:113)
kotlin.reflect.jvm.internal.KCallableImpl.call(KCallableImpl.kt:106)
kotlin.reflect.full.KCallables.callSuspend(KCallables.kt:51)
io.kotlintest.specs.AbstractAnnotationSpec$createTestCase$1.invokeSuspend(AbstractAnnotationSpec.kt:80)
io.kotlintest.specs.AbstractAnnotationSpec$createTestCase$1.invoke(AbstractAnnotationSpec.kt)
io.kotlintest.runner.jvm.TestCaseExecutor$executeTest$supervisorJob$1$invokeSuspend$$inlined$map$lambda$1.invokeSuspend(TestCaseExecutor.kt:133)
kotlin.coroutines.jvm.internal.BaseContinuationImpl.resumeWith(ContinuationImpl.kt:33)
kotlinx.coroutines.DispatchedTask.run(Dispatched.kt:241)
java.base/java.util.concurrent.ThreadPoolExecutor.runWorker(ThreadPoolExecutor.java:1128)
java.base/java.util.concurrent.ThreadPoolExecutor$Worker.run(ThreadPoolExecutor.java:628)
java.base/java.lang.Thread.run(Thread.java:834)


06.01.2020-14:44:27: ContextScope: java.lang.RuntimeException: testException.message
de.gapps.utils.misc.CatchTest.testCatch(CatchTest.kt:15)
java.base/jdk.internal.reflect.NativeMethodAccessorImpl.invoke0(Native Method)
java.base/jdk.internal.reflect.NativeMethodAccessorImpl.invoke(NativeMethodAccessorImpl.java:62)
java.base/jdk.internal.reflect.DelegatingMethodAccessorImpl.invoke(DelegatingMethodAccessorImpl.java:43)
java.base/java.lang.reflect.Method.invoke(Method.java:566)
kotlin.reflect.jvm.internal.calls.CallerImpl$Method.callMethod(CallerImpl.kt:97)
kotlin.reflect.jvm.internal.calls.CallerImpl$Method$Instance.call(CallerImpl.kt:113)
kotlin.reflect.jvm.internal.KCallableImpl.call(KCallableImpl.kt:106)
kotlin.reflect.full.KCallables.callSuspend(KCallables.kt:51)
io.kotlintest.specs.AbstractAnnotationSpec$createTestCase$1.invokeSuspend(AbstractAnnotationSpec.kt:80)
io.kotlintest.specs.AbstractAnnotationSpec$createTestCase$1.invoke(AbstractAnnotationSpec.kt)
io.kotlintest.runner.jvm.TestCaseExecutor$executeTest$supervisorJob$1$invokeSuspend$$inlined$map$lambda$1.invokeSuspend(TestCaseExecutor.kt:133)
kotlin.coroutines.jvm.internal.BaseContinuationImpl.resumeWith(ContinuationImpl.kt:33)
kotlinx.coroutines.DispatchedTask.run(Dispatched.kt:241)
java.base/java.util.concurrent.ThreadPoolExecutor.runWorker(ThreadPoolExecutor.java:1128)
java.base/java.util.concurrent.ThreadPoolExecutor$Worker.run(ThreadPoolExecutor.java:628)
java.base/java.lang.Thread.run(Thread.java:834)


06.01.2020-14:44:27: ContextScope: java.lang.AssertionError: executed is true.message
de.gapps.utils.coroutines.BuilderTest$testLaunchExDelayed$1$2.invokeSuspend(BuilderTest.kt:33)
kotlin.coroutines.jvm.internal.BaseContinuationImpl.resumeWith(ContinuationImpl.kt:33)
kotlinx.coroutines.ResumeModeKt.resumeMode(ResumeMode.kt:67)
kotlinx.coroutines.DispatchedKt.resume(Dispatched.kt:319)
kotlinx.coroutines.DispatchedKt.dispatch(Dispatched.kt:301)
kotlinx.coroutines.CancellableContinuationImpl.dispatchResume(CancellableContinuationImpl.kt:250)
kotlinx.coroutines.CancellableContinuationImpl.resumeImpl(CancellableContinuationImpl.kt:260)
kotlinx.coroutines.CancellableContinuationImpl.resumeUndispatched(CancellableContinuationImpl.kt:332)
kotlinx.coroutines.EventLoopImplBase$DelayedResumeTask.run(EventLoop.common.kt:483)
kotlinx.coroutines.EventLoopImplBase.processNextEvent(EventLoop.common.kt:270)
kotlinx.coroutines.BlockingCoroutine.joinBlocking(Builders.kt:79)
kotlinx.coroutines.BuildersKt__BuildersKt.runBlocking(Builders.kt:54)
kotlinx.coroutines.BuildersKt.runBlocking(Unknown Source)
kotlinx.coroutines.BuildersKt__BuildersKt.runBlocking$default(Builders.kt:36)
kotlinx.coroutines.BuildersKt.runBlocking$default(Unknown Source)
de.gapps.utils.coroutines.BuilderTest.testLaunchExDelayed(BuilderTest.kt:24)
java.base/jdk.internal.reflect.NativeMethodAccessorImpl.invoke0(Native Method)
java.base/jdk.internal.reflect.NativeMethodAccessorImpl.invoke(NativeMethodAccessorImpl.java:62)
java.base/jdk.internal.reflect.DelegatingMethodAccessorImpl.invoke(DelegatingMethodAccessorImpl.java:43)
java.base/java.lang.reflect.Method.invoke(Method.java:566)
kotlin.reflect.jvm.internal.calls.CallerImpl$Method.callMethod(CallerImpl.kt:97)
kotlin.reflect.jvm.internal.calls.CallerImpl$Method$Instance.call(CallerImpl.kt:113)
kotlin.reflect.jvm.internal.KCallableImpl.call(KCallableImpl.kt:106)
kotlin.reflect.full.KCallables.callSuspend(KCallables.kt:51)
io.kotlintest.specs.AbstractAnnotationSpec$createTestCase$1.invokeSuspend(AbstractAnnotationSpec.kt:80)
io.kotlintest.specs.AbstractAnnotationSpec$createTestCase$1.invoke(AbstractAnnotationSpec.kt)
io.kotlintest.runner.jvm.TestCaseExecutor$executeTest$supervisorJob$1$invokeSuspend$$inlined$map$lambda$1.invokeSuspend(TestCaseExecutor.kt:133)
kotlin.coroutines.jvm.internal.BaseContinuationImpl.resumeWith(ContinuationImpl.kt:33)
kotlinx.coroutines.DispatchedTask.run(Dispatched.kt:241)
java.base/java.util.concurrent.ThreadPoolExecutor.runWorker(ThreadPoolExecutor.java:1128)
java.base/java.util.concurrent.ThreadPoolExecutor$Worker.run(ThreadPoolExecutor.java:628)
java.base/java.lang.Thread.run(Thread.java:834)


null